2025-08-13 22:18:47,765 INFO    Thread-116 (_run_job):7156 [wandb_setup.py:_flush():80] Current SDK version is 0.21.0
2025-08-13 22:18:47,765 INFO    Thread-116 (_run_job):7156 [wandb_setup.py:_flush():80] Configure stats pid to 7156
2025-08-13 22:18:47,765 INFO    Thread-116 (_run_job):7156 [wandb_setup.py:_flush():80] Loading settings from C:\Users\tobys\.config\wandb\settings
2025-08-13 22:18:47,765 INFO    Thread-116 (_run_job):7156 [wandb_setup.py:_flush():80] Loading settings from c:\Users\tobys\Desktop\STAR\dev_notebooks\heston\sweep\wandb\settings
2025-08-13 22:18:47,765 INFO    Thread-116 (_run_job):7156 [wandb_setup.py:_flush():80] Loading settings from environment variables
2025-08-13 22:18:47,765 INFO    Thread-116 (_run_job):7156 [wandb_init.py:setup_run_log_directory():703] Logging user logs to c:\Users\tobys\Desktop\STAR\dev_notebooks\heston\sweep\wandb\run-20250813_221847-zpdwvnfg\logs\debug.log
2025-08-13 22:18:47,766 INFO    Thread-116 (_run_job):7156 [wandb_init.py:setup_run_log_directory():704] Logging internal logs to c:\Users\tobys\Desktop\STAR\dev_notebooks\heston\sweep\wandb\run-20250813_221847-zpdwvnfg\logs\debug-internal.log
2025-08-13 22:18:47,766 INFO    Thread-116 (_run_job):7156 [wandb_init.py:monkeypatch_ipython():622] configuring jupyter hooks <wandb.sdk.wandb_init._WandbInit object at 0x0000025B83E0AB60>
2025-08-13 22:18:47,766 INFO    Thread-116 (_run_job):7156 [wandb_init.py:init():830] calling init triggers
2025-08-13 22:18:47,766 INFO    Thread-116 (_run_job):7156 [wandb_init.py:init():835] wandb.init called with sweep_config: {'N_boundary': 500, 'N_pde': 2500, 'N_terminal': 500, 'hidden_layers': 2, 'learning_rate': 0.0024, 'neurons_per_layer': 256, 'num_epochs': 5000, 'w_boundary': 0.03460323089295216, 'w_pde': 9.183656295627934, 'w_terminal': 1.9680988928217624}
config: {'_wandb': {}}
2025-08-13 22:18:47,766 INFO    Thread-116 (_run_job):7156 [wandb_init.py:init():871] starting backend
2025-08-13 22:18:47,986 INFO    Thread-116 (_run_job):7156 [wandb_init.py:init():874] sending inform_init request
2025-08-13 22:18:47,987 INFO    Thread-116 (_run_job):7156 [wandb_init.py:init():882] backend started and connected
2025-08-13 22:18:47,989 INFO    Thread-116 (_run_job):7156 [wandb_run.py:_config_callback():1363] config_cb None None {'N_boundary': 500, 'N_pde': 2500, 'N_terminal': 500, 'hidden_layers': 2, 'learning_rate': 0.0024, 'neurons_per_layer': 256, 'num_epochs': 5000, 'w_boundary': 0.03460323089295216, 'w_pde': 9.183656295627934, 'w_terminal': 1.9680988928217624}
2025-08-13 22:18:47,989 INFO    Thread-116 (_run_job):7156 [wandb_run.py:_label_probe_notebook():1304] probe notebook
2025-08-13 22:18:47,990 INFO    Thread-116 (_run_job):7156 [wandb_init.py:init():953] updated telemetry
2025-08-13 22:18:48,015 INFO    Thread-116 (_run_job):7156 [wandb_init.py:init():977] communicating run to backend with 90.0 second timeout
2025-08-13 22:18:48,886 INFO    Thread-116 (_run_job):7156 [wandb_init.py:init():1029] starting run threads in backend
2025-08-13 22:18:49,029 INFO    Thread-116 (_run_job):7156 [wandb_run.py:_console_start():2458] atexit reg
2025-08-13 22:18:49,029 INFO    Thread-116 (_run_job):7156 [wandb_run.py:_redirect():2306] redirect: wrap_raw
2025-08-13 22:18:49,029 INFO    Thread-116 (_run_job):7156 [wandb_run.py:_redirect():2375] Wrapping output streams.
2025-08-13 22:18:49,029 INFO    Thread-116 (_run_job):7156 [wandb_run.py:_redirect():2398] Redirects installed.
2025-08-13 22:18:49,030 INFO    Thread-116 (_run_job):7156 [wandb_init.py:init():1075] run started, returning control to user process
2025-08-13 22:21:21,038 INFO    Thread-10 (_heartbeat):7156 [retry.py:__call__():173] [no run ID] Retry attempt failed:
Traceback (most recent call last):
  File "c:\Users\tobys\miniconda3\envs\star-pinn\lib\site-packages\urllib3\connection.py", line 198, in _new_conn
    sock = connection.create_connection(
  File "c:\Users\tobys\miniconda3\envs\star-pinn\lib\site-packages\urllib3\util\connection.py", line 85, in create_connection
    raise err
  File "c:\Users\tobys\miniconda3\envs\star-pinn\lib\site-packages\urllib3\util\connection.py", line 73, in create_connection
    sock.connect(sa)
OSError: [WinError 10051] A socket operation was attempted to an unreachable network

The above exception was the direct cause of the following exception:

Traceback (most recent call last):
  File "c:\Users\tobys\miniconda3\envs\star-pinn\lib\site-packages\urllib3\connectionpool.py", line 787, in urlopen
    response = self._make_request(
  File "c:\Users\tobys\miniconda3\envs\star-pinn\lib\site-packages\urllib3\connectionpool.py", line 488, in _make_request
    raise new_e
  File "c:\Users\tobys\miniconda3\envs\star-pinn\lib\site-packages\urllib3\connectionpool.py", line 464, in _make_request
    self._validate_conn(conn)
  File "c:\Users\tobys\miniconda3\envs\star-pinn\lib\site-packages\urllib3\connectionpool.py", line 1093, in _validate_conn
    conn.connect()
  File "c:\Users\tobys\miniconda3\envs\star-pinn\lib\site-packages\urllib3\connection.py", line 704, in connect
    self.sock = sock = self._new_conn()
  File "c:\Users\tobys\miniconda3\envs\star-pinn\lib\site-packages\urllib3\connection.py", line 213, in _new_conn
    raise NewConnectionError(
urllib3.exceptions.NewConnectionError: <urllib3.connection.HTTPSConnection object at 0x0000025B8822C460>: Failed to establish a new connection: [WinError 10051] A socket operation was attempted to an unreachable network

The above exception was the direct cause of the following exception:

Traceback (most recent call last):
  File "c:\Users\tobys\miniconda3\envs\star-pinn\lib\site-packages\requests\adapters.py", line 667, in send
    resp = conn.urlopen(
  File "c:\Users\tobys\miniconda3\envs\star-pinn\lib\site-packages\urllib3\connectionpool.py", line 841, in urlopen
    retries = retries.increment(
  File "c:\Users\tobys\miniconda3\envs\star-pinn\lib\site-packages\urllib3\util\retry.py", line 519, in increment
    raise MaxRetryError(_pool, url, reason) from reason  # type: ignore[arg-type]
urllib3.exceptions.MaxRetryError: HTTPSConnectionPool(host='api.wandb.ai', port=443): Max retries exceeded with url: /graphql (Caused by NewConnectionError('<urllib3.connection.HTTPSConnection object at 0x0000025B8822C460>: Failed to establish a new connection: [WinError 10051] A socket operation was attempted to an unreachable network'))

During handling of the above exception, another exception occurred:

Traceback (most recent call last):
  File "c:\Users\tobys\miniconda3\envs\star-pinn\lib\site-packages\wandb\sdk\lib\retry.py", line 134, in __call__
    result = self._call_fn(*args, **kwargs)
  File "c:\Users\tobys\miniconda3\envs\star-pinn\lib\site-packages\wandb\sdk\internal\internal_api.py", line 397, in execute
    return self.client.execute(*args, **kwargs)  # type: ignore
  File "c:\Users\tobys\miniconda3\envs\star-pinn\lib\site-packages\wandb\vendor\gql-0.2.0\wandb_gql\client.py", line 52, in execute
    result = self._get_result(document, *args, **kwargs)
  File "c:\Users\tobys\miniconda3\envs\star-pinn\lib\site-packages\wandb\vendor\gql-0.2.0\wandb_gql\client.py", line 60, in _get_result
    return self.transport.execute(document, *args, **kwargs)
  File "c:\Users\tobys\miniconda3\envs\star-pinn\lib\site-packages\wandb\sdk\lib\gql_request.py", line 58, in execute
    request = self.session.post(self.url, **post_args)
  File "c:\Users\tobys\miniconda3\envs\star-pinn\lib\site-packages\requests\sessions.py", line 637, in post
    return self.request("POST", url, data=data, json=json, **kwargs)
  File "c:\Users\tobys\miniconda3\envs\star-pinn\lib\site-packages\requests\sessions.py", line 589, in request
    resp = self.send(prep, **send_kwargs)
  File "c:\Users\tobys\miniconda3\envs\star-pinn\lib\site-packages\requests\sessions.py", line 703, in send
    r = adapter.send(request, **kwargs)
  File "c:\Users\tobys\miniconda3\envs\star-pinn\lib\site-packages\requests\adapters.py", line 700, in send
    raise ConnectionError(e, request=request)
requests.exceptions.ConnectionError: HTTPSConnectionPool(host='api.wandb.ai', port=443): Max retries exceeded with url: /graphql (Caused by NewConnectionError('<urllib3.connection.HTTPSConnection object at 0x0000025B8822C460>: Failed to establish a new connection: [WinError 10051] A socket operation was attempted to an unreachable network'))
2025-08-13 22:22:20,260 INFO    Thread-116 (_run_job):7156 [wandb_run.py:_finish():2224] finishing run tobiassafie-drexel-university/Heston-Weight-Sweeps-3/zpdwvnfg
2025-08-13 22:22:20,261 INFO    Thread-116 (_run_job):7156 [jupyter.py:save_history():480] not saving jupyter history
2025-08-13 22:22:20,261 INFO    Thread-116 (_run_job):7156 [jupyter.py:save_ipynb():404] not saving jupyter notebook
2025-08-13 22:22:20,261 INFO    Thread-116 (_run_job):7156 [wandb_init.py:_jupyter_teardown():607] cleaning up jupyter logic
2025-08-13 22:22:20,261 INFO    Thread-116 (_run_job):7156 [wandb_run.py:_atexit_cleanup():2423] got exitcode: 0
2025-08-13 22:22:20,261 INFO    Thread-116 (_run_job):7156 [wandb_run.py:_restore():2405] restore
2025-08-13 22:22:20,261 INFO    Thread-116 (_run_job):7156 [wandb_run.py:_restore():2411] restore done
2025-08-13 23:18:28,676 INFO    Thread-116 (_run_job):7156 [wandb_run.py:_footer_history_summary_info():3903] rendering history
2025-08-13 23:18:28,676 INFO    Thread-116 (_run_job):7156 [wandb_run.py:_footer_history_summary_info():3935] rendering summary
2025-08-13 23:18:28,676 INFO    Thread-116 (_run_job):7156 [wandb_run.py:_footer_sync_info():3864] logging synced files
